Workbook

Sheet Sheet Overview
A1: TAB | B1: DEFINITION
A2: Sheet Overview | B2: Provides an overview of all the tabs within the database
A3: Headers | B3: Defines all the headers of the columns found in CRR 2025
A4: CRR 2025 | B4: Final Coral Reef Restoration (CRR) Database, with all coral reef restoration activities listed as individual rows, including their corresponding information or details
A5: Glossary | B5: Contains definitions for all possible options appearing in the dropdown lists of CRR 2025; this also serves as the source for data validation ranges
A6: Municipality | B6: Lists all regions, provinces, municipalities, and municipality codes found in CRR 2025; this also serves as a source for data validation
A7: Panel Format | B7: Shows a panel format comparing the 2023 (final) and 2025 (draft) iterations of the CRR database; served as a draft for the final CRR 2025 database
A8: 2025 | B8: Draft 2025 iteration of the CRR database
A9: 2024 | B9: Draft 2024 iteration of the CRR database
A10: 2023 | B10: 2023 iteration of the CRR database, with most entries considered in the Matorres et al. (2024) publication
A11: 2023 PubDel Entries | B11: Contains all the entries in the CRR 2023 iteration that were deleted in the 2025 iteration
A13: HIDDEN SHEETS FOR DATA VALIDATION/DROPDOWN
A14: Interventions | B14: Contains the master list of all general and specific coral reef restoration intervention types; used as the source for dropdowns and cross-referencing
A15: [Interventions]DD1 | B15: Lists unique general intervention categories; used in dropdowns for filtering or input validation in the CRR 2025 tab
A16: [Interventions]DD2 | B16: Lists all specific restoration methods, aligned with the general intervention categories for validation purposes
A17: [Mun]DD1 | B17: Lists all Philippine regions; used as a data validation source for the Region field in CRR 2025
A18: [Mun]DD2 | B18: Lists all provinces under their corresponding regions; used to validate Province entries
A19: [Mun]DD3 | B19: Lists all municipalities under their corresponding provinces, along with the official PSGC municipal codes; used to validate Municipality entries

Sheet Headers
A1: SECTIONS | B1: HEADERS | C1: DEFINITION
A2: Entry Information | B2: ID | C2: Number indicating the order in which the restoration project was encoded into the database
B3: Unique_key | C3: Code that uniquely identifies a restoration project in the database
B4: Year_add | C4: Year in which the project was added to the database
B5: Status | C5: Indicates if the project was part of the Matorres et al. (2024)
B6: Change_type | C6: Describes what type of change was made to the entry compared to its version in Matorres et al. (2024)
B7: Recheck | C7: Indicates whether the project entry has been rechecked after standardization of database rules
A8: Project Location and Timeline | B8: Region | C8: Region where the restoration project is located
B9: Province | C9: Province where the restoration project is located
B10: Municipality | C10: Municipality where the restoration project is located
B11: Municipality_code | C11: Standardised municipality code based on the official coding system from NAMRIA
B12: Restoration_project_title | C12: The given title of the restoration project
B13: Project_locality | C13: Specific site where the project is located, which may include the barangay, named location, or geographic coordinates
B14: Year_estab | C14: Year the restoration project was established on site
B15: Project_start | C15: Start date of the project
B16: Project_end | C16: End date of the project
A17: Restoration Approach | B17: Gen_method | C17: General restoration method used by the project
B18: Specific_method | C18: Specific restoration technique applied by the project
B19: AR_material_type | C19: Type of material used in the artificial reef restoration project
B20: AR_specific_structure | C20: Specific material used in the artificial reef restoration project
B21: Nursery_type_loc | C21: Location of the coral nursery, whether in-situ or ex-situ
B22: Nursery_type_design | C22: Type of nursery used in the coral gardening restoration project
B23: Method_specifics | C23: Other specific information on the material used in ALL of the restoration projects, as indicated in the reference material
A24: Project Objectives | B24: Motivation | C24: Primary motivation or objective behind the project, based on the classification from Boström-Einarsson et al. (2020)
B25: Motivation_code | C25: Codes assigned to the primary motivation
B26: Stated_objective | C26: Project objective/motivation as indicated in the reference material; not discriminating between main and other objectives
A27: Funding and Scale | B27: Funding_agency | C27: Name of the funding agency
B28: Fund_type | C28: General purpose or intended use of the funding provided
B29: Funder_loc | C29: Indicates whether the funder is based locally or internationally
B30: Funder_sector | C30: Broad category of the organisation providing the funding, based on its institutional nature
B31: Funder_specific_entity | C31: Specific funder categorization
B32: Total_funding | C32: Amount of funding in PHP provided or total cost of restoration activity
B33: Total_area | C33: Total area covered by the restoration project
B34: Total_units | C34: Total number of individual restoration units used in the project
A35: Implementers and Partners | B35: Implement_insti | C35: Name of institution that established the restoration project
B36: Proponent_sector | C36: General type of institution that established the project
B37: Proponent_specific_entity | C37: Specific proponent categorization
B38: Partners_public | C38: Government partners -- national to local
B39: Partners_private | C39: Private, dive centers, NGO, CSOs, or academic partners that collaborated in the project
B40: Partners_communities | C40: Community partners in the project
...

Sheet CRR 2025
A1: ID | B1: Unique_key | C1: Year_add | D1: Status | E1: Change_type | F1: Rechecked? | G1: Region | H1: Province | I1: Municipality | J1: Municipality_code | K1: Restoration_project_title | L1: Project_locality | M1: Year_estab | N1: Project_start | O1: Project_end | P1: Gen_method | Q1: Specific_method | R1: AR_material_type | S1: AR_specific_structure | T1: Nursery_type_loc | U1: Nursery_type_design | V1: Method_specifics | W1: Motivation | X1: Motivation_code | Y1: Stated_objective | Z1: Funding_agency | AA1: Fund_type | AB1: Funder_loc | AC1: Funder_sector | AD1: Funder_specific_entity | AE1: Total_funding | AF1: Total_area | AG1: Total_units | AH1: Implement_insti | AI1: Proponent_sector | AJ1: Proponent_specific_entity | AK1: Partners_public | AL1: Partners_private | AM1: Partners_communities | AN1: Literature_type | AO1: Source_type | AP1: Reference | AQ1: Link | AR1: Contact_name | AS1: Contact_details | AT1: Remarks
A2: 0034 | B2: =CONCATENATE(C2, "-", J2, "-", M2, "-", A2) -> 2023-PH015501000-2021-0034 | C2: =IF(OR(D2="Published", D2="Unpublished"), 2023, IF(D2="New", 2025, "")) -> 2023 | D2: Published | E2: Modified | F2: Yes | G2: I | H2: Pangasinan | I2: Agno | J2: PH015501000 | K2: Abig Pangasinan | L2: Site in Brgy Boboy | M2: 2021 | N2: Unknown | O2: Unknown | P2: Substrate Enhancement | Q2: Artificial Reef | R2: Concrete | S2: Concrete tripod | T2: Not applicable | U2: Not applicable | V2: Concrete tripod | W2: "Provide alternative, sustainable livelihood opportunities", "Reestablish a self-sustaining, functioning reef ecosystem", Reduce population declines and ecosystem degradation | X2: M2, M5, M4 | Y2: Provide livelihood opportunities to fisherfolk; breeding grounds for fishes and other marine resources that will boost fish production and food security in the locality; boost aqua-tourism | Z2: PLGU | AA2: Development | AB2: Local | AC2: Government - LGU | AD2: PLGU | AE2: Unknown | AF2: Unknown | AG2: 45 units | AH2: PLGU | AI2: Government - LGU | AJ2: PLGU | AK2: BFAR; MLGU | AL2: Unknown | AM2: Local fisherfolks tapped to be "Bantay Dagat" | AN2: Grey literature | AO2: News/Press Release | AP2: Austria, H. (2021, April 9). Artificial reef project gives livelihood to Pangasinan fisherfolk. Philippine News Agency. https://www.pna.gov.ph/articles/1136282 | AQ2: https://www.pna.gov.ph/articles/1136282 | AR2: Rosario Segundina Gaerlan, BFAR Ilocos Region officer-in-charge regional director | AS2: Unknown
A3: 0362 | B3: =CONCATENATE(C3, "-", J3, "-", M3, "-", A3) -> 2023-PH104319000-2000-0362 | C3: =IF(OR(D3="Published", D3="Unpublished"), 2023, IF(D3="New", 2025, "")) -> 2023 | D3: Published | E3: Modified | F3: Yes | G3: X | H3: Misamis Oriental | I3: Medina | J3: PH104319000 | K3: Acantasia Project | L3: Site in Gingoong Bay | M3: 2000 | N3: 2000 | O3: Unknown | P3: Asexual Propagation | Q3: Direct Transplantation | R3: Not applicable | S3: Not applicable | T3: Not applicable | U3: Not applicable | V3: Coral transplantation | W3: "Reestablish a self-sustaining, functioning reef ecosystem" | X3: M2 | Y3: Restoring coral reef cover | Z3: Duka Bay Resort Inc. | AA3: Development | AB3: Local | AC3: Private | AD3: Private | AE3: Unknown | AF3: Unknown | AG3: Unknown | AH3: Duka Bay Resort Inc. | AI3: Private | AJ3: Private | AK3: Unknown | AL3: Ernesto Pelaez; Eduardo Yap | AM3: Unknown | AN3: Grey literature | AO3: News/Press Release | AP3: dela Cruz, R. (2006, April 24). Duka Bay: An ecological business paradigm. PhilStar Global. https://www.philstar.com/business/business-as-usual/2006/04/24/333050/duka-bay-ecological-business-paradigm | AQ3: https://www.philstar.com/business/business-as-usual/2006/04/24/333050/duka-bay-ecological-business-paradigm | AR3: Ernesto Pelaez | AS3: 0917 794 2759; 088-3312499
A4: 0279 | B4: =CONCATENATE(C4, "-", J4, "-", M4, "-", A4) -> 2025-PH072220000-2024-0279 | C4: =IF(OR(D4="Published", D4="Unpublished"), 2023, IF(D4="New", 2025, "")) -> 2025 | D4: New | E4: New | F4: No | G4: VII | H4: Cebu | I4: Cordova | J4: PH072220000 | K4: ACIAR Coral Reef Restoration Project | L4: Site inside Alegria MPA | M4: 2024 | N4: 2021 | O4: 2025 | P4: Sexual Propagation | Q4: Larval Enhancement | R4: Not applicable | S4: Not applicable | T4: Not applicable | U4: Not applicable | V4: Larval reseeding; "Mactan tiles" | W4: "Reestablish a self-sustaining, functioning reef ecosystem" | X4: M2 | Y4: Reef restoration | Z4: ACIAR | AA4: Research | AB4: International | AC4: Donor Agency | AD4: Donor Agency | AE4: Unknown | AF4: Unknown | AG4: Unknown | AH4: Southern Cross University | AI4: Academe | AJ4: Foreign Academic Entity | AK4: UP MSI; MLGU | AL4: Shangri-La Dive Resort | AM4: Unknown | AN4: Survey | AO4: Personal communication | AP4: Personal communication | AQ4: Unknown | AR4: Unknown | AS4: Unknown
A5: 0290 | B5: =CONCATENATE(C5, "-", J5, "-", M5, "-", A5) -> 2025-PH072226000-2024-0290 | C5: =IF(OR(D5="Published", D5="Unpublished"), 2023, IF(D5="New", 2025, "")) -> 2025 | D5: New | E5: New | F5: No | G5: VII | H5: Cebu | I5: City of Lapu-Lapu | J5: PH072226000 | K5: ACIAR Coral Reef Restoration Project | L5: Site inside MPA in Mactan Shangri-La Resort | M5: 2024 | N5: 2021 | O5: 2025 | P5: Sexual Propagation | Q5: Larval Enhancement | R5: Not applicable | S5: Not applicable | T5: Not applicable | U5: Not applicable | V5: Larval reseeding; "Mactan tiles" | W5: "Reestablish a self-sustaining, functioning reef ecosystem" | X5: M2 | Y5: Reef restoration | Z5: ACIAR | AA5: Research | AB5: International | AC5: Donor Agency | AD5: Donor Agency | AE5: Unknown | AF5: Unknown | AG5: Unknown | AH5: Southern Cross University | AI5: Academe | AJ5: Foreign Academic Entity | AK5: UP MSI; CLGU | AL5: Shangri-La Dive Resort | AM5: Unknown | AN5: Survey | AO5: Personal communication | AP5: Personal communication | AQ5: Unknown | AR5: Unknown | AS5: Unknown
A6: 0041 | B6: =CONCATENATE(C6, "-", J6, "-", M6, "-", A6) -> 2023-PH015503000-2018-0041 | C6: =IF(OR(D6="Published", D6="Unpublished"), 2023, IF(D6="New", 2025, "")) -> 2023 | D6: Published | E6: Modified | F6: No | G6: I | H6: Pangasinan | I6: City of Alaminos | J6: PH015503000 | K6: ACIAR Coral Reef Restoration Project | L6: Site in HINP | M6: 2018 | N6: Unknown | O6: Unknown | P6: Sexual Propagation | Q6: Larval Enhancement | R6: Not applicable | S6: Not applicable | T6: Not applicable | U6: Not applicable | V6: Larval reseeding | W6: "Reestablish a self-sustaining, functioning reef ecosystem" | X6: M2 | Y6: Enhanced larval supply and recruitment to replenish reef corals on degraded reefs | Z6: ACIAR | AA6: Development | AB6: International | AC6: Donor Agency | AD6: Donor Agency | AE6: Unknown | AF6: Unknown | AG6: Unknown | AH6: UP-MSI | AI6: Academe | AJ6: Public Academic Institutions | AK6: CLGU | AL6: Southern Cross University | AM6: Unknown | AN6: Survey | AO6: Personal communication | AP6: Personal communication | AQ6: Unknown | AR6: Unknown | AS6: Unknown
A7: 0048 | B7: =CONCATENATE(C7, "-", J7, "-", M7, "-", A7) -> 2023-PH015505000-2018-0048 | C7: =IF(OR(D7="Published", D7="Unpublished"), 2023, IF(D7="New", 2025, "")) -> 2023 | D7: Published | E7: Modified | F7: No | G7: I | H7: Pangasinan | I7: Anda | J7: PH015505000 | K7: ACIAR Coral Reef Restoration Project | L7: Site in Tanduyong Island | M7: 2018 | N7: Unknown | O7: Unknown | P7: Sexual Propagation | Q7: Larval Enhancement | R7: Not applicable | S7: Not applicable | T7: Not applicable | U7: Not applicable | V7: Larval reseeding | W7: "Reestablish a self-sustaining, functioning reef ecosystem" | X7: M2 | Y7: Enhanced larval supply and recruitment to replenish reef corals on degraded reefs | Z7: ACIAR | AA7: Development | AB7: International | AC7: Donor Agency | AD7: Donor Agency | AE7: Unknown | AF7: Unknown | AG7: Unknown | AH7: UP MSI | AI7: Academe | AJ7: Public Academic Institutions | AK7: Unknown | AL7: Southern Cross University | AM7: Unknown | AN7: Survey | AO7: Personal communication | AP7: Personal communication | AQ7: Unknown | AR7: Unknown | AS7: Unknown
A8: 0051 | B8: =CONCATENATE(C8, "-", J8, "-", M8, "-", A8) -> 2023-PH015505000-2013-0051 | C8: =IF(OR(D8="Published", D8="Unpublished"), 2023, IF(D8="New", 2025, "")) -> 2023 | D8: Published | E8: Modified | F8: Yes | G8: I | H8: Pangasinan | I8: Anda | J8: PH015505000 | K8: ACIAR Coral Reef Restoration Project | L8: Site in Magsaysay Reef (N 16.3213889, E 120.03388888888888) | M8: 2013 | N8: 2013 | O8: 2015 | P8: Sexual Propagation | Q8: Larval Enhancement | R8: Not applicable | S8: Not applicable | T8: Not applicable | U8: Not applicable | V8: Larval reseeding (settement tiles from larvae in fine-mesh enclosures) | W8: Scientific Research | X8: M7 | Y8: Test the effect of supplying large numbers of coral larvae on replicate degraded reef areas | Z8: ACIAR | AA8: Development | AB8: International | AC8: Donor Agency | AD8: Donor Agency | AE8: Unknown | AF8: Unknown | AG8: Unknown | AH8: Southern Cross University | AI8: Academe | AJ8: Foreign Academic Entity | AK8: University of the Philippines Diliman; UP MSI | AL8: Unknown | AM8: Unknown | AN8: Peer-reviewed | AO8: Journal Article | AP8: Dela Cruz, D. W., & Harrison, P. L. (2017). Enhanced larval supply and recruitment can replenish reef corals on degraded reefs. Scientific Reports 7(1). DOI:10.1038/s41598-017-14546-y | AQ8: https://www.researchgate.net/publication/320629634_Enhanced_larval_supply_and_recruitment_can_replenish_reef_corals_on_degraded_reefs; https://www.ncbi.nlm.nih.gov/pmc/articles/PMC7685485/ | AR8: Dr. Dexter dela Cruz | AS8: Unknown
A9: 0052 | B9: =CONCATENATE(C9, "-", J9, "-", M9, "-", A9) -> 2023-PH015505000-2016-0052 | C9: =IF(OR(D9="Published", D9="Unpublished"), 2023, IF(D9="New", 2025, "")) -> 2023 | D9: Published | E9: Modified | F9: Yes | G9: I | H9: Pangasinan | I9: Anda | J9: PH015505000 | K9: ACIAR Coral Reef Restoration Project | L9: Site in Magsaysay Reef | M9: 2016 | N9: 2016 | O9: 2019 | P9: Sexual Propagation | Q9: Larval Enhancement | R9: Not applicable | S9: Not applicable | T9: Not applicable | U9: Not applicable | V9: Larval reseeding (settement tiles from larvae in fine-mesh enclosures) | W9: Scientific Research | X9: M7 | Y9: Build on pilot study to quantify effects of increased larval supply, assess long term restoration outcomes and develop techniques for capturing large volume of coral spawns | Z9: ACIAR | AA9: Development | AB9: International | AC9: Donor Agency | AD9: Donor Agency | AE9: Unknown | AF9: Unknown | AG9: Unknown | AH9: Southern Cross University | AI9: Academe | AJ9: Foreign Academic Entity | AK9: University of the Philippines Diliman; UP MSI | AL9: Unknown | AM9: Unknown | AN9: Peer-reviewed | AO9: Journal Article | AP9: Harrison, P. L., Dela Cruz, D. W., Cameron, K., & Cabaitan, P. (2021). Increased Coral Larval Supply Enhances Recruitment for Coral and Fish Habitat Restoration. Frontiers in Marine Science, 8. DOI:10.3389/fmars.2021.750210 | AQ9: https://www.researchgate.net/publication/356725969_Increased_Coral_Larval_Supply_Enhances_Recruitment_for_Coral_and_Fish_Habitat_Restoration | AR9: Dr. Peter Harrison / Dr. Dexter dela Cruz | AS9: Unknown
A10: 0053 | B10: =CONCATENATE(C10, "-", J10, "-", M10, "-", A10) -> 2023-PH015505000-2021-0053 | C10: =IF(OR(D10="Published", D10="Unpublished"), 2023, IF(D10="New", 2025, "")) -> 2023 | D10: Published | E10: Modified | F10: No | G10: I | H10: Pangasinan | I10: Anda | J10: PH015505000 | K10: ACIAR Coral Reef Restoration Project | L10: Unknown | M10: 2021 | N10: 2021 | O10: 2025 | P10: Sexual Propagation | Q10: Larval Enhancement | R10: Not applicable | S10: Not applicable | T10: Not applicable | U10: Not applicable | V10: Larval reseeding | W10: Unknown | X10: UNK | Y10: Unknown | Z10: ACIAR | AA10: Development | AB10: International | AC10: Donor Agency | AD10: Donor Agency | AE10: Unknown | AF10: Unknown | AG10: Unknown | AH10: Southern Cross University | AI10: Academe | AJ10: Foreign Academic Entity | AK10: University of the Philippines Diliman; UP MSI | AL10: Unknown | AM10: Unknown | AN10: Survey | AO10: Personal communication | AP10: Unknown | AQ10: Unknown | AR10: Unknown | AS10: Unknown
A11: 0128 | B11: =CONCATENATE(C11, "-", J11, "-", M11, "-", A11) -> 2023-PH041019000-2012-0128 | C11: =IF(OR(D11="Published", D11="Unpublished"), 2023, IF(D11="New", 2025, "")) -> 2023 | D11: Published | E11: Modified | F11: Yes | G11: IV-A | H11: Batangas | I11: Nasugbu | J11: PH041019000 | K11: Adopt a Coral | L11: Site in Brgy Natiyuan | M11: 2012 | N11: Unknown | O11: Unknown | P11: Asexual Propagation, Substrate Enhancement | Q11: Artificial Reef, Direct Transplantation | R11: Concrete | S11: Concrete block | T11: Not applicable | U11: Not applicable | V11: Concrete block; coral transplantation | W11: "Reestablish a self-sustaining, functioning reef ecosystem", "Provide alternative, sustainable livelihood opportunities", Promote coral reef conservation stewardship | X11: M2, M6, M5 | Y11: Restore coral and marine environment; tourist attraction; promote image of the Rotary | Z11: Rotary Club of Makati Urdaneta | AA11: Development | AB11: Local | AC11: CSO | AD11: CSO | AE11: Unknown | AF11: Unknown | AG11: 200 blocks | AH11: Rotary Club of Makati Urdaneta | AI11: CSO | AJ11: CSO | AK11: MLGU; PNP; MENRO | AL11: Unknown | AM11: Unknown | AN11: Grey literature | AO11: News/Press Release | AP11: Pecayo, J. (2012, May 17). Rotary Club launches "Adopt a Coral" in Nasugbu. Manila-US Times. https://manilaustimes.wordpress.com/2012/05/17/rotary-club-launches-adopt-a-coral-in-nasugbu/ | AQ11: https://manilaustimes.wordpress.com/2012/05/17/rotary-club-launches-adopt-a-coral-in-nasugbu/; https://feed.org.ph/media-centre/press-releases-2015/adopt-a-coral-project-extends-its-outreach-through-feed/ | AR11: Unknown | AS11: Unknown
A12: 0356 | B12: =CONCATENATE(C12, "-", J12, "-", M12, "-", A12) -> 2023-PH104311000-Unknown-0356 | C12: =IF(OR(D12="Published", D12="Unpublished"), 2023, IF(D12="New", 2025, "")) -> 2023 | D12: Published | E12: Modified | F12: No | G12: X | H12: Misamis Oriental | I12: Jasaan | J12: PH104311000 | K12: Agutayan Artificial Reef Project and Giant Clam Seeding | L12: Site in Agutayan Island | M12: Unknown | N12: Unknown | O12: Unknown | P12: Substrate Enhancement | Q12: Artificial Reef | R12: Hybrid | S12: Tires, Steel frame, Unspecified concrete structure | T12: Not applicable | U12: Not applicable | V12: tires, concrete, steel | W12: Promote coral reef conservation stewardship | X12: M6 | Y12: Corporate social responsibility | Z12: Nestle | AA12: Development | AB12: Local | AC12: Private | AD12: Private | AE12: Unknown | AF12: Unknown | AG12: Unknown | AH12: Nestle | AI12: Private | AJ12: Private | AK12: Unknown | AL12: Rudy Trillanes | AM12: Unknown | AN12: Grey literature | AO12: Blog/Website | AP12: cbartazo (2008, April 16). Diving at Agutayan Island…October 13, 2007). Life in the Great Beyond [blog]. https://cbartazo.com/tag/agutayan-island/ | AQ12: https://cbartazo.com/tag/agutayan-island/; https://www.philstar.com/business/business-as-usual/2008/08/25/81412/rudy-trillanes-coffee-man; https://www.lakwatsero.com/dive-report/my-yearend-dive-at-agutayan-island-marine-sanctuary/ | AR12: Unknown | AS12: Unknown
A13: 0102 | B13: =CONCATENATE(C13, "-", J13, "-", M13, "-", A13) -> 2023-PH037105000-2022-0102 | C13: =IF(OR(D13="Published", D13="Unpublished"), 2023, IF(D13="New", 2025, "")) -> 2023 | D13: Published | E13: Modified | F13: No | G13: III | H13: Zambales | I13: Iba | J13: PH037105000 | K13: An Integrated Approach to Marine Resource Conservation and Sustainable Fisheries Management to Strengthen Coastal Communities in Zambales | L13: Unknown | M13: 2022 | N13: 2022 | O13: 2024 | P13: Asexual Propagation, Sexual Propagation | Q13: Larval Enhancement, Coral Gardening | R13: Not applicable | S13: Not applicable | T13: In-situ | U13: Unknown | V13: Coral trees; tree nursery | W13: Reduce population declines and ecosystem degradation, Promote coral reef conservation stewardship | X13: M4, M6 | Y13: Enhance fish stock; community education/engagement | Z13: Mead Foundation | AA13: Development | AB13: International | AC13: NGO | AD13: NGO | AE13: Unknown | AF13: Unknown | AG13: Unknown | AH13: Mead Foundation; UP MSI | AI13: NGO | AJ13: NGO | AK13: MLGU; DFAT | AL13: MERF; University of Southern Cross; ACIAR | AM13: Unknown | AN13: Survey | AO13: Questionnaire | AP13: Survey | AQ13: Unknown | AR13: Karen Chan; Mead Foundation | AS13: karen@mead-foundation.org; 09175111210
A14: 0230 | B14: =CONCATENATE(C14, "-", J14, "-", M14, "-", A14) -> 2023-PH060412000-Unknown-0230 | C14: =IF(OR(D14="Published", D14="Unpublished"), 2023, IF(D14="New", 2025, "")) -> 2023 | D14: Published | E14: Modified | F14: No | G14: VI | H14: Aklan | I14: Malay | J14: PH060412000 | K14: APEC PPSTI-5 | L14: Unknown | M14: Unknown | N14: Unknown | O14: Unknown | P14: Asexual Propagation | Q14: Coral Gardening | R14: Not applicable | S14: Not applicable | T14: In-situ | U14: CNU | V14: CNU | W14: Unknown | X14: UNK | Y14: Unknown | Z14: DOST-PCAARRD | AA14: Development | AB14: Local | AC14: Government - NGA | AD14: DOST | AE14: Unknown | AF14: Unknown | AG14: Unknown | AH14: Sangkalikasan Producers Cooperative, DOST | AI14: CSO | AJ14: CSO | AK14: Philippine Coast Guard; DOST | AL14: Sangkalikasan Producers Cooperative | AM14: Unknown | AN14: Grey literature | AO14: News/Press Release | AP14: Carlos, M. B., Surara, C. A., & Mananghaya, R. A. (2016, February 12). Restoring the country's coral reefs through Filippinovation. DOST-PCAARRD. https://www.pcaarrd.dost.gov.ph/index.php/quick-information-dispatch-qid-articles/restoring-the-country-s-coral-reefs-through-filipinnovation | AQ14: https://www.pcaarrd.dost.gov.ph/index.php/quick-information-dispatch-qid-articles/restoring-the-country-s-coral-reefs-through-filipinnovation | AR14: Unknown | AS14: Unknown
A15: 0374 | B15: =CONCATENATE(C15, "-", J15, "-", M15, "-", A15) -> 2023-PH112319000-2007-0374 | C15: =IF(OR(D15="Published", D15="Unpublished"), 2023, IF(D15="New", 2025, "")) -> 2023 | D15: Published | E15: Modified | F15: No | G15: XI | H15: Davao del Norte | I15: City of Tagum | J15: PH112319000 | K15: Artificial Coral Reef Project | L15: Site inside 22-ha MPA in Brgy Liboganon | M15: 2007 | N15: 2007 | O15: 2016 | P15: Substrate Enhancement | Q15: Artificial Reef | R15: Engineered/Advanced | S15: Reef ball | T15: Not applicable | U15: Not applicable | V15: Reef ball | W15: "Reestablish a self-sustaining, functioning reef ecosystem" | X15: M2 | Y15: Improve marine life | Z15: CLGU | AA15: Development | AB15: Local | AC15: Government - LGU | AD15: CLGU | AE15: Unknown | AF15: 3.00 ha | AG15: 200 reef balls | AH15: CLGU | AI15: Government - LGU | AJ15: CLGU | AK15: DENR | AL15: Unknown | AM15: Unknown | AN15: Grey literature | AO15: News/Press Release | AP15: Mayuga, J. (2017, March 26). Tagum City cites artificial reef project, supports "MPA networking" initiative. Business Mirror. https://businessmirror.com.ph/2017/03/26/tagum-city-cites-artificial-reef-project-supports-mpa-networking-initiative/ | AQ15: https://businessmirror.com.ph/2017/03/26/tagum-city-cites-artificial-reef-project-supports-mpa-networking-initiative/; https://mobile.facebook.com/DistinctivelyDavao/posts/tagum-city-cites-artificial-reef-project-supports-mpa-networking-initiativetagum/283751215413471/?_rdc=1&_rdr | AR15: Unknown | AS15: Unknown
A16: 0404 | B16: =CONCATENATE(C16, "-", J16, "-", M16, "-", A16) -> 2023-PH166724000-2018-0404 | C16: =IF(OR(D16="Published", D16="Unpublished"), 2023, IF(D16="New", 2025, "")) -> 2023 | D16: Published | E16: Modified | F16: No | G16: XIII | H16: Surigao del Norte | I16: City of Surigao | J16: PH166724000 | K16: Artificial Coral Reefs | L16: Site in Brgy Sugbay and Brgy Manjagao | M16: 2018 | N16: Unknown | O16: Unknown | P16: Substrate Enhancement | Q16: Artificial Reef | R16: Concrete | S16: Unspecified concrete structure | T16: Not applicable | U16: Not applicable | V16: Concrete | W16: "Reestablish a self-sustaining, functioning reef ecosystem" | X16: M2 | Y16: Shelter and breeding ground for fish | Z16: Unknown | AA16: Development | AB16: Unknown | AC16: Unknown | AD16: Unknown | AE16: Unknown | AF16: Unknown | AG16: Unknown | AH16: CLGU | AI16: Government - LGU | AJ16: CLGU | AK16: Unknown | AL16: Unknown | AM16: Unknown | AN16: Grey literature | AO16: News/Press Release | AP16: Bombo Butuan Newsdesk (2018, March 19). Artificial coral reefs, gimontar sa Surigao City. Bombo Radyo. https://butuan.bomboradyo.com/artificial-coral-reefs-gimontar-sa-surigao-city/ | AQ16: https://butuan.bomboradyo.com/artificial-coral-reefs-gimontar-sa-surigao-city/ | AR16: Unknown | AS16: Unknown
A17: 0391 | B17: =CONCATENATE(C17, "-", J17, "-", M17, "-", A17) -> 2023-PH128004000-2009-0391 | C17: =IF(OR(D17="Published", D17="Unpublished"), 2023, IF(D17="New", 2025, "")) -> 2023 | D17: Published | E17: Modified | F17: Yes | G17: XII | H17: Sarangani | I17: Maasim | J17: PH128004000 | K17: Artificial Reef Deployment Project | L17: Unknown | M17: 2009 | N17: 2009 | O17: 2015 | P17: Substrate Enhancement | Q17: Artificial Reef | R17: Concrete | S17: Concrete domes | T17: Not applicable | U17: Not applicable | V17: Domes | W17: "Reestablish a self-sustaining, functioning reef ecosystem", Reduce population declines and ecosystem degradation, Promote coral reef conservation stewardship | X17: M2, M4, M6 | Y17: Restore marine and coastal life; restore fishery resources; breeding ground; corporate social responsibility | Z17: Conrado and Ladislawa Alcantara Foundation; Holcim Cement | AA17: Development | AB17: Local | AC17: NGO | AD17: NGO | AE17: Unknown | AF17: Unknown | AG17: 4,300 units | AH17: Conrado and Ladislawa Alcantara Foundation | AI17: NGO | AJ17: NGO | AK17: MLGU | AL17: Sarangani Energy Corporation | AM17: Unknown | AN17: Grey literature | AO17: News/Press Release | AP17: The Philippine Star (2015, November 23). Sarangani's Kamanga Marine Eco-tourism Park and Sanctuary cited as one of Philippine's best. PhilStar Global. https://www.philstar.com/other-sections/the-good-news/2015/11/23/1524749/saranganis-kamanga-marine-eco-tourism-park-and-sanctuary-cited-one-philippines-best | AQ17: https://www.philstar.com/other-sections/the-good-news/2015/11/23/1524749/saranganis-kamanga-marine-eco-tourism-park-and-sanctuary-cited-one-philippines-best; https://www.sunstar.com.ph/more-articles/artificial-reef-to-be-deployed-in-sarangani-bay | AR17: Unknown | AS17: Unknown | AT17: Project_end is based on the year the article was published (as it was mentioned that restoration started in 2009).
A18: 0393 | B18: =CONCATENATE(C18, "-", J18, "-", M18, "-", A18) -> 2023-PH128006000-2015-0393 | C18: =IF(OR(D18="Published", D18="Unpublished"), 2023, IF(D18="New", 2025, "")) -> 2023 | D18: Published | E18: Modified | F18: No | G18: XII | H18: Sarangani | I18: Malapatan | J18: PH128006000 | K18: Artificial Reef Deployment Project | L18: Unknown | M18: 2015 | N18: Unknown | O18: Unknown | P18: Substrate Enhancement | Q18: Artificial Reef | R18: Concrete | S18: Concrete domes | T18: Not applicable | U18: Not applicable | V18: Domes | W18: Unknown | X18: UNK | Y18: Unknown | Z18: Conrado and Ladislawa Alcantara Foundation | AA18: Development | AB18: Local | AC18: NGO | AD18: NGO | AE18: Unknown | AF18: Unknown | AG18: 300 units | AH18: Conrado and Ladislawa Alcantara Foundation | AI18: NGO | AJ18: NGO | AK18: Unknown | AL18: Unknown | AM18: Unknown | AN18: Grey literature | AO18: Blog/Website | AP18: Artificial Reef Dome. (n.d.). Our work: Environment protection and conservation projects. Conrado & Ladislawa Alcantara Foundation. https://clafi.org/our_work_categories/environment-protection-and-conservation-projects/ | AQ18: https://clafi.org/our_work_categories/environment-protection-and-conservation-projects/ | AR18: Unknown | AS18: Unknown
A19: 0003 | B19: =CONCATENATE(C19, "-", J19, "-", M19, "-", A19) -> 2023-PH012812000-1986-0003 | C19: =IF(OR(D19="Published", D19="Unpublished"), 2023, IF(D19="New", 2025, "")) -> 2023 | D19: Published | E19: Modified | F19: Yes | G19: I | H19: Ilocos Norte | I19: City of Laoag | J19: PH012812000 | K19: Artificial Reef Development Program | L19: Site in Calayab | M19: 1986 | N19: 1985 | O19: 1987 | P19: Substrate Enhancement | Q19: Artificial Reef | R19: Tires | S19: Tires | T19: Not applicable | U19: Not applicable | V19: Tires | W19: "Reestablish a self-sustaining, functioning reef ecosystem", Reduce population declines and ecosystem degradation, "Provide alternative, sustainable livelihood opportunities" | X19: M2, M4, M5 | Y19: Support the government's food productivity, environmental protection and enhancement efforts; Support sustenance fishery; enhance and restore habitats; costal fishery management | Z19: BFAR | AA19: Development | AB19: Local | AC19: Government - NGA | AD19: BFAR | AE19: Unknown | AF19: Unknown | AG19: 10 TM | AH19: BFAR | AI19: Government - NGA | AJ19: BFAR | AK19: Ministry of Human Settlements; Government organizations | AL19: NGOs | AM19: People's organizations; Fisher's associations | AN19: Peer-reviewed | AO19: Conference Proceeding | AP19: Balgos, M. C. (1995). Evaluation of artificial reef development in the Philippines. In J. L. Munro & M. C. Balgos (Eds.), Artificial reefs in the Philippines (ICLARM Conference Proceedings No. 49, pp. 6–22). International Center for Living Aquatic Resources Management (ICLARM). | AQ19: https://core.ac.uk/download/pdf/6515223.pdf; https://www.ircwash.org/sites/default/files/802-PH90-8920.pdf | AR19: Miriam Balgos | AS19: Unknown
A20: 0005 | B20: =CONCATENATE(C20, "-", J20, "-", M20, "-", A20) -> 2023-PH012817000-1986-0005 | C20: =IF(OR(D20="Published", D20="Unpublished"), 2023, IF(D20="New", 2025, "")) -> 2023 | D20: Published | E20: Modified | F20: Yes | G20: I | H20: Ilocos Norte | I20: Pasuquin | J20: PH012817000 | K20: Artificial Reef Development Program | L20: Site in Puyupuyan | M20: 1986 | N20: 1985 | O20: 1987 | P20: Substrate Enhancement | Q20: Artificial Reef | R20: Tires | S20: Tires | T20: Not applicable | U20: Not applicable | V20: Tires | W20: "Reestablish a self-sustaining, functioning reef ecosystem", Reduce population declines and ecosystem degradation, "Provide alternative, sustainable livelihood opportunities" | X20: M2, M4, M5 | Y20: Support the government's food productivity, environmental protection and enhancement efforts; Support sustenance fishery; enhance and restore habitats; costal fishery management | Z20: BFAR | AA20: Development | AB20: Local | AC20: Government - NGA | AD20: BFAR | AE20: Unknown | AF20: Unknown | AG20: 10 TM | AH20: BFAR | AI20: Government - NGA | AJ20: BFAR | AK20: Ministry of Human Settlements; Government organizations | AL20: NGOs | AM20: People's organizations; Fisher's associations | AN20: Peer-reviewed | AO20: Conference Proceeding | AP20: Balgos, M. C. (1995). Evaluation of artificial reef development in the Philippines. In J. L. Munro & M. C. Balgos (Eds.), Artificial reefs in the Philippines (ICLARM Conference Proceedings No. 49, pp. 6–22). International Center for Living Aquatic Resources Management (ICLARM). | AQ20: https://core.ac.uk/download/pdf/6515223.pdf; https://www.ircwash.org/sites/default/files/802-PH90-8920.pdf | AR20: Miriam Balgos | AS20: Unknown
A21: 0008 | B21: =CONCATENATE(C21, "-", J21, "-", M21, "-", A21) -> 2023-PH012905000-1986-0008 | C21: =IF(OR(D21="Published", D21="Unpublished"), 2023, IF(D21="New", 2025, "")) -> 2023 | D21: Published | E21: Modified | F21: Yes | G21: I | H21: Ilocos Sur | I21: Cabugao | J21: PH012905000 | K21: Artificial Reef Development Program | L21: Site in Pung-os | M21: 1986 | N21: 1985 | O21: 1987 | P21: Substrate Enhancement | Q21: Artificial Reef | R21: Tires | S21: Tires | T21: Not applicable | U21: Not applicable | V21: Tires | W21: "Reestablish a self-sustaining, functioning reef ecosystem", Reduce population declines and ecosystem degradation, "Provide alternative, sustainable livelihood opportunities" | X21: M2, M4, M5 | Y21: Support the government's food productivity, environmental protection and enhancement efforts; Support sustenance fishery; enhance and restore habitats; costal fishery management | Z21: BFAR | AA21: Development | AB21: Local | AC21: Government - NGA | AD21: BFAR | AE21: Unknown | AF21: Unknown | AG21: 10 TM | AH21: BFAR | AI21: Government - NGA | AJ21: BFAR | AK21: Ministry of Human Settlements; Government organizations | AL21: NGOs | AM21: People's organizations; Fisher's associations | AN21: Peer-reviewed | AO21: Conference Proceeding | AP21: Balgos, M. C. (1995). Evaluation of artificial reef development in the Philippines. In J. L. Munro & M. C. Balgos (Eds.), Artificial reefs in the Philippines (ICLARM Conference Proceedings No. 49, pp. 6–22). International Center for Living Aquatic Resources Management (ICLARM). | AQ21: https://core.ac.uk/download/pdf/6515223.pdf; https://www.ircwash.org/sites/default/files/802-PH90-8920.pdf | AR21: Miriam Balgos | AS21: Unknown
A22: 0009 | B22: =CONCATENATE(C22, "-", J22, "-", M22, "-", A22) -> 2023-PH012905000-1986-0009 | C22: =IF(OR(D22="Published", D22="Unpublished"), 2023, IF(D22="New", 2025, "")) -> 2023 | D22: Published | E22: Modified | F22: Yes | G22: I | H22: Ilocos Sur | I22: Cabugao | J22: PH012905000 | K22: Artificial Reef Development Program | L22: Site in Namruangan | M22: 1986 | N22: 1985 | O22: 1987 | P22: Substrate Enhancement | Q22: Artificial Reef | R22: Tires | S22: Tires | T22: Not applicable | U22: Not applicable | V22: Tires | W22: "Reestablish a self-sustaining, functioning reef ecosystem", Reduce population declines and ecosystem degradation, "Provide alternative, sustainable livelihood opportunities" | X22: M2, M4, M5 | Y22: Support the government's food productivity, environmental protection and enhancement efforts; Support sustenance fishery; enhance and restore habitats; costal fishery management | Z22: BFAR | AA22: Development | AB22: Local | AC22: Government - NGA | AD22: BFAR | AE22: Unknown | AF22: Unknown | AG22: 10 TM | AH22: BFAR | AI22: Government - NGA | AJ22: BFAR | AK22: Ministry of Human Settlements; Government organizations | AL22: NGOs | AM22: People's organizations; Fisher's associations | AN22: Peer-reviewed | AO22: Conference Proceeding | AP22: Balgos, M. C. (1995). Evaluation of artificial reef development in the Philippines. In J. L. Munro & M. C. Balgos (Eds.), Artificial reefs in the Philippines (ICLARM Conference Proceedings No. 49, pp. 6–22). International Center for Living Aquatic Resources Management (ICLARM). | AQ22: https://core.ac.uk/download/pdf/6515223.pdf; https://www.ircwash.org/sites/default/files/802-PH90-8920.pdf | AR22: Miriam Balgos | AS22: Unknown
A23: 0011 | B23: =CONCATENATE(C23, "-", J23, "-", M23, "-", A23) -> 2023-PH012906000-1986-0011 | C23: =IF(OR(D23="Published", D23="Unpublished"), 2023, IF(D23="New", 2025, "")) -> 2023 | D23: Published | E23: Modified | F23: Yes | G23: I | H23: Ilocos Sur | I23: City of Candon | J23: PH012906000 | K23: Artificial Reef Development Program | L23: Site in Calongbuyan | M23: 1986 | N23: 1985 | O23: 1987 | P23: Substrate Enhancement | Q23: Artificial Reef | R23: Tires | S23: Tires | T23: Not applicable | U23: Not applicable | V23: Tires | W23: "Reestablish a self-sustaining, functioning reef ecosystem", Reduce population declines and ecosystem degradation, "Provide alternative, sustainable livelihood opportunities" | X23: M2, M4, M5 | Y23: Support the government's food productivity, environmental protection and enhancement efforts; Support sustenance fishery; enhance and restore habitats; costal fishery management | Z23: BFAR | AA23: Development | AB23: Local | AC23: Government - NGA | AD23: BFAR | AE23: Unknown | AF23: Unknown | AG23: 8 TM | AH23: BFAR | AI23: Government - NGA | AJ23: BFAR | AK23: Ministry of Human Settlements; Government organizations | AL23: NGOs | AM23: People's organizations; Fisher's associations | AN23: Peer-reviewed | AO23: Conference Proceeding | AP23: Balgos, M. C. (1995). Evaluation of artificial reef development in the Philippines. In J. L. Munro & M. C. Balgos (Eds.), Artificial reefs in the Philippines (ICLARM Conference Proceedings No. 49, pp. 6–22). International Center for Living Aquatic Resources Management (ICLARM). | AQ23: https://core.ac.uk/download/pdf/6515223.pdf; https://www.ircwash.org/sites/default/files/802-PH90-8920.pdf | AR23: Miriam Balgos | AS23: Unknown
A24: 0013 | B24: =CONCATENATE(C24, "-", J24, "-", M24, "-", A24) -> 2023-PH012914000-1986-0013 | C24: =IF(OR(D24="Published", D24="Unpublished"), 2023, IF(D24="New", 2025, "")) -> 2023 | D24: Published | E24: Modified | F24: Yes | G24: I | H24: Ilocos Sur | I24: Narvacan | J24: PH012914000 | K24: Artificial Reef Development Program | L24: Site in Pantoc | M24: 1986 | N24: 1985 | O24: 1987 | P24: Substrate Enhancement | Q24: Artificial Reef | R24: Tires | S24: Tires | T24: Not applicable | U24: Not applicable | V24: Tires | W24: "Reestablish a self-sustaining, functioning reef ecosystem", Reduce population declines and ecosystem degradation, "Provide alternative, sustainable livelihood opportunities" | X24: M2, M4, M5 | Y24: Support the government's food productivity, environmental protection and enhancement efforts; Support sustenance fishery; enhance and restore habitats; costal fishery management | Z24: BFAR | AA24: Development | AB24: Local | AC24: Government - NGA | AD24: BFAR | AE24: Unknown | AF24: Unknown | AG24: 8 TM | AH24: BFAR | AI24: Government - NGA | AJ24: BFAR | AK24: Ministry of Human Settlements; Government organizations | AL24: NGOs | AM24: People's organizations; Fisher's associations | AN24: Peer-reviewed | AO24: Conference Proceeding | AP24: Balgos, M. C. (1995). Evaluation of artificial reef development in the Philippines. In J. L. Munro & M. C. Balgos (Eds.), Artificial reefs in the Philippines (ICLARM Conference Proceedings No. 49, pp. 6–22). International Center for Living Aquatic Resources Management (ICLARM). | AQ24: https://core.ac.uk/download/pdf/6515223.pdf; https://www.ircwash.org/sites/default/files/802-PH90-8920.pdf | AR24: Miriam Balgos | AS24: Unknown
A25: 0014 | B25: =CONCATENATE(C25, "-", J25, "-", M25, "-", A25) -> 2023-PH012924000-1986-0014 | C25: =IF(OR(D25="Published", D25="Unpublished"), 2023, IF(D25="New", 2025, "")) -> 2023 | D25: Published | E25: Modified | F25: Yes | G25: I | H25: Ilocos Sur | I25: Santa Cruz | J25: PH012924000 | K25: Artificial Reef Development Program | L25: Site in Pilar | M25: 1986 | N25: 1985 | O25: 1987 | P25: Substrate Enhancement | Q25: Artificial Reef | R25: Tires | S25: Tires | T25: Not applicable | U25: Not applicable | V25: Tires | W25: "Reestablish a self-sustaining, functioning reef ecosystem", Reduce population declines and ecosystem degradation, "Provide alternative, sustainable livelihood opportunities" | X25: M2, M4, M5 | Y25: Support the government's food productivity, environmental protection and enhancement efforts; Support sustenance fishery; enhance and restore habitats; costal fishery management | Z25: BFAR | AA25: Development | AB25: Local | AC25: Government - NGA | AD25: BFAR | AE25: Unknown | AF25: Unknown | AG25: 8 TM | AH25: BFAR | AI25: Government - NGA | AJ25: BFAR | AK25: Ministry of Human Settlements; Government organizations | AL25: NGOs | AM25: People's organizations; Fisher's associations | AN25: Peer-reviewed | AO25: Conference Proceeding | AP25: Balgos, M. C. (1995). Evaluation of artificial reef development in the Philippines. In J. L. Munro & M. C. Balgos (Eds.), Artificial reefs in the Philippines (ICLARM Conference Proceedings No. 49, pp. 6–22). International Center for Living Aquatic Resources Management (ICLARM). | AQ25: https://core.ac.uk/download/pdf/6515223.pdf; https://www.ircwash.org/sites/default/files/802-PH90-8920.pdf | AR25: Miriam Balgos | AS25: Unknown
A26: 0016 | B26: =CONCATENATE(C26, "-", J26, "-", M26, "-", A26) -> 2023-PH012930000-1986-0016 | C26: =IF(OR(D26="Published", D26="Unpublished"), 2023, IF(D26="New", 2025, "")) -> 2023 | D26: Published | E26: Modified | F26: Yes | G26: I | H26: Ilocos Sur | I26: Sinait | J26: PH012930000 | K26: Artificial Reef Development Program | L26: Site in Katipunan | M26: 1986 | N26: 1985 | O26: 1987 | P26: Substrate Enhancement | Q26: Artificial Reef | R26: Tires | S26: Tires | T26: Not applicable | U26: Not applicable | V26: Tires | W26: "Reestablish a self-sustaining, functioning reef ecosystem", Reduce population declines and ecosystem degradation, "Provide alternative, sustainable livelihood opportunities" | X26: M2, M4, M5 | Y26: Support the government's food productivity, environmental protection and enhancement efforts; Support sustenance fishery; enhance and restore habitats; costal fishery management | Z26: BFAR | AA26: Development | AB26: Local | AC26: Government - NGA | AD26: BFAR | AE26: Unknown | AF26: Unknown | AG26: 10 TM | AH26: BFAR | AI26: Government - NGA | AJ26: BFAR | AK26: Ministry of Human Settlements; Government organizations | AL26: NGOs | AM26: People's organizations; Fisher's associations | AN26: Peer-reviewed | AO26: Conference Proceeding | AP26: Balgos, M. C. (1995). Evaluation of artificial reef development in the Philippines. In J. L. Munro & M. C. Balgos (Eds.), Artificial reefs in the Philippines (ICLARM Conference Proceedings No. 49, pp. 6–22). International Center for Living Aquatic Resources Management (ICLARM). | AQ26: https://core.ac.uk/download/pdf/6515223.pdf; https://www.ircwash.org/sites/default/files/802-PH90-8920.pdf | AR26: Miriam Balgos | AS26: Unknown
A27: 0017 | B27: =CONCATENATE(C27, "-", J27, "-", M27, "-", A27) -> 2023-PH012933000-1986-0017 | C27: =IF(OR(D27="Published", D27="Unpublished"), 2023, IF(D27="New", 2025, "")) -> 2023 | D27: Published | E27: Modified | F27: Yes | G27: I | H27: Ilocos Sur | I27: Tagudin | J27: PH012933000 | K27: Artificial Reef Development Program | L27: Site in Becques | M27: 1986 | N27: 1985 | O27: 1987 | P27: Substrate Enhancement | Q27: Artificial Reef | R27: Tires | S27: Tires | T27: Not applicable | U27: Not applicable | V27: Tires | W27: "Reestablish a self-sustaining, functioning reef ecosystem", Reduce population declines and ecosystem degradation, "Provide alternative, sustainable livelihood opportunities" | X27: M2, M4, M5 | Y27: Support the government's food productivity, environmental protection and enhancement efforts; Support sustenance fishery; enhance and restore habitats; costal fishery management | Z27: BFAR | AA27: Development | AB27: Local | AC27: Government - NGA | AD27: BFAR | AE27: Unknown | AF27: Unknown | AG27: 7 TM | AH27: BFAR | AI27: Government - NGA | AJ27: BFAR | AK27: Ministry of Human Settlements; Government organizations | AL27: NGOs | AM27: People's organizations; Fisher's associations | AN27: Peer-reviewed | AO27: Conference Proceeding | AP27: Balgos, M. C. (1995). Evaluation of artificial reef development in the Philippines. In J. L. Munro & M. C. Balgos (Eds.), Artificial reefs in the Philippines (ICLARM Conference Proceedings No. 49, pp. 6–22). International Center for Living Aquatic Resources Management (ICLARM). | AQ27: https://core.ac.uk/download/pdf/6515223.pdf; https://www.ircwash.org/sites/default/files/802-PH90-8920.pdf | AR27: Miriam Balgos | AS27: Unknown
A28: 0018 | B28: =CONCATENATE(C28, "-", J28, "-", M28, "-", A28) -> 2023-PH012934000-1986-0018 | C28: =IF(OR(D28="Published", D28="Unpublished"), 2023, IF(D28="New", 2025, "")) -> 2023 | D28: Published | E28: Modified | F28: Yes | G28: I | H28: Ilocos Sur | I28: City of Vigan | J28: PH012934000 | K28: Artificial Reef Development Program | L28: Site in San Pedro | M28: 1986 | N28: 1985 | O28: 1987 | P28: Substrate Enhancement | Q28: Artificial Reef | R28: Tires | S28: Tires | T28: Not applicable | U28: Not applicable | V28: Tires | W28: "Reestablish a self-sustaining, functioning reef ecosystem", Reduce population declines and ecosystem degradation, "Provide alternative, sustainable livelihood opportunities" | X28: M2, M4, M5 | Y28: Support the government's food productivity, environmental protection and enhancement efforts; Support sustenance fishery; enhance and restore habitats; costal fishery management | Z28: BFAR | AA28: Development | AB28: Local | AC28: Government - NGA | AD28: BFAR | AE28: Unknown | AF28: Unknown | AG28: 9 TM | AH28: BFAR | AI28: Government - NGA | AJ28: BFAR | AK28: Ministry of Human Settlements; Government organizations | AL28: NGOs | AM28: People's organizations; Fisher's associations | AN28: Peer-reviewed | AO28: Conference Proceeding | AP28: Balgos, M. C. (1995). Evaluation of artificial reef development in the Philippines. In J. L. Munro & M. C. Balgos (Eds.), Artificial reefs in the Philippines (ICLARM Conference Proceedings No. 49, pp. 6–22). International Center for Living Aquatic Resources Management (ICLARM). | AQ28: https://core.ac.uk/download/pdf/6515223.pdf; https://www.ircwash.org/sites/default/files/802-PH90-8920.pdf | AR28: Miriam Balgos | AS28: Unknown
A29: 0020 | B29: =CONCATENATE(C29, "-", J29, "-", M29, "-", A29) -> 2023-PH013302000-1986-0020 | C29: =IF(OR(D29="Published", D29="Unpublished"), 2023, IF(D29="New", 2025, "")) -> 2023 | D29: Published | E29: Modified | F29: Yes | G29: I | H29: La Union | I29: Aringay | J29: PH013302000 | K29: Artificial Reef Development Program | L29: Site in Dulao | M29: 1986 | N29: 1985 | O29: 1987 | P29: Substrate Enhancement | Q29: Artificial Reef | R29: Tires | S29: Tires | T29: Not applicable | U29: Not applicable | V29: Tires | W29: "Reestablish a self-sustaining, functioning reef ecosystem", Reduce population declines and ecosystem degradation, "Provide alternative, sustainable livelihood opportunities" | X29: M2, M4, M5 | Y29: Support the government's food productivity, environmental protection and enhancement efforts; Support sustenance fishery; enhance and restore habitats; costal fishery management | Z29: BFAR | AA29: Development | AB29: Local | AC29: Government - NGA | AD29: BFAR | AE29: Unknown | AF29: Unknown | AG29: 10 TM | AH29: BFAR | AI29: Government - NGA | AJ29: BFAR | AK29: Ministry of Human Settlements; Government organizations | AL29: NGOs | AM29: People's organizations; Fisher's associations | AN29: Peer-reviewed | AO29: Conference Proceeding | AP29: Balgos, M. C. (1995). Evaluation of artificial reef development in the Philippines. In J. L. Munro & M. C. Balgos (Eds.), Artificial reefs in the Philippines (ICLARM Conference Proceedings No. 49, pp. 6–22). International Center for Living Aquatic Resources Management (ICLARM). | AQ29: https://core.ac.uk/download/pdf/6515223.pdf; https://www.ircwash.org/sites/default/files/802-PH90-8920.pdf | AR29: Miriam Balgos | AS29: Unknown
A30: 0024 | B30: =CONCATENATE(C30, "-", J30, "-", M30, "-", A30) -> 2023-PH013306000-1986-0024 | C30: =IF(OR(D30="Published", D30="Unpublished"), 2023, IF(D30="New", 2025, "")) -> 2023 | D30: Published | E30: Modified | F30: Yes | G30: I | H30: La Union | I30: Bangar | J30: PH013306000 | K30: Artificial Reef Development Program | L30: Site in Mindoro | M30: 1986 | N30: 1985 | O30: 1987 | P30: Substrate Enhancement | Q30: Artificial Reef | R30: Unknown | S30: Unknown | T30: Not applicable | U30: Not applicable | V30: Unknown | W30: "Reestablish a self-sustaining, functioning reef ecosystem", Reduce population declines and ecosystem degradation, "Provide alternative, sustainable livelihood opportunities" | X30: M2, M4, M5 | Y30: Support the government's food productivity, environmental protection and enhancement efforts; Support sustenance fishery; enhance and restore habitats; costal fishery management | Z30: BFAR | AA30: Development | AB30: Local | AC30: Government - NGA | AD30: BFAR | AE30: Unknown | AF30: Unknown | AG30: Unknown | AH30: BFAR | AI30: Government - NGA | AJ30: BFAR | AK30: Ministry of Human Settlements; Government organizations | AL30: NGOs | AM30: People's organizations; Fisher's associations | AN30: Peer-reviewed | AO30: Conference Proceeding | AP30: Balgos, M. C. (1995). Evaluation of artificial reef development in the Philippines. In J. L. Munro & M. C. Balgos (Eds.), Artificial reefs in the Philippines (ICLARM Conference Proceedings No. 49, pp. 6–22). International Center for Living Aquatic Resources Management (ICLARM). | AQ30: https://core.ac.uk/download/pdf/6515223.pdf; https://www.ircwash.org/sites/default/files/802-PH90-8920.pdf | AR30: Miriam Balgos | AS30: Unknown
... A73: 0409 | B73: =CONCATENATE(C73, "-", J73, "-", M73, "-", A73) -> 2023-PH133900000-1985-0409 | C73: =IF(OR(D73="Published", D73="Unpublished"), 2023, IF(D73="New", 2025, "")) -> 2023 | D73: Published | E73: Modified | F73: Yes | G73: NCR | H73: Metro Manila | I73: City of Manila | J73: PH133900000 | K73: Artificial Reef Development Program | L73: Site in Manila Bay Fish Sanctuary (Port Area) fronting Navotas and Tondo area in Manila and Orion in Bataan | M73: 1985 | N73: 1985 | O73: 1987 | P73: Substrate Enhancement | Q73: Artificial Reef | R73: Tires | S73: Tires | T73: Not applicable | U73: Not applicable | V73: Tires | W73: "Reestablish a self-sustaining, functioning reef ecosystem", Reduce population declines and ecosystem degradation, "Provide alternative, sustainable livelihood opportunities" | X73: M2, M4, M5 | Y73: Support the government's food productivity, environmental protection and enhancement efforts; Support sustenance fishery; enhance and restore habitats; costal fishery management | Z73: BFAR | AA73: Development | AB73: Local | AC73: Government - NGA | AD73: BFAR | AE73: Unknown | AF73: Unknown | AG73: 8 TM | AH73: BFAR | AI73: Government - NGA | AJ73: BFAR | AK73: Ministry of Human Settlements; Government organizations | AL73: NGOs | AM73: People's organizations; Fisher's associations | AN73: Peer-reviewed | AO73: Conference Proceeding | AP73: Balgos, M. C. (1995). Evaluation of artificial reef development in the Philippines. In J. L. Munro & M. C. Balgos (Eds.), Artificial reefs in the Philippines (ICLARM Conference Proceedings No. 49, pp. 6–22). International Center for Living Aquatic Resources Management (ICLARM). | AQ73: https://core.ac.uk/download/pdf/6515223.pdf | AR73: Miriam Balgos | AS73: Unknown
A74: 0410 | B74: =CONCATENATE(C74, "-", J74, "-", M74, "-", A74) -> 2023-PH064501000-1986-0410 | C74: =IF(OR(D74="Published", D74="Unpublished"), 2023, IF(D74="New", 2025, "")) -> 2023 | D74: Published | E74: Modified | F74: Yes | G74: NIR | H74: Negros Occidental | I74: City of Bacolod | J74: PH064501000 | K74: Artificial Reef Development Program | L74: Site in Banago | M74: 1986 | N74: 1985 | O74: 1987 | P74: Substrate Enhancement | Q74: Artificial Reef | R74: Tires | S74: Tires | T74: Not applicable | U74: Not applicable | V74: Tires | W74: "Reestablish a self-sustaining, functioning reef ecosystem", Reduce population declines and ecosystem degradation, "Provide alternative, sustainable livelihood opportunities" | X74: M2, M4, M5 | Y74: Support the government's food productivity, environmental protection and enhancement efforts; Support sustenance fishery; enhance and restore habitats; costal fishery management | Z74: BFAR | AA74: Development | AB74: Local | AC74: Government - NGA | AD74: BFAR | AE74: Unknown | AF74: Unknown | AG74: 10 TM | AH74: BFAR | AI74: Government - NGA | AJ74: BFAR | AK74: Ministry of Human Settlements; Government organizations | AL74: NGOs | AM74: People's organizations; Fisher's associations | AN74: Peer-reviewed | AO74: Conference Proceeding | AP74: Balgos, M. C. (1995). Evaluation of artificial reef development in the Philippines. In J. L. Munro & M. C. Balgos (Eds.), Artificial reefs in the Philippines (ICLARM Conference Proceedings No. 49, pp. 6–22). International Center for Living Aquatic Resources Management (ICLARM). | AQ74: https://core.ac.uk/download/pdf/6515223.pdf | AR74: Miriam Balgos | AS74: Unknown | AT74: 10 modules were also deployed in Sangwa, Bangsua in Negros Occidental but this place does not match any current records
A75: 0428 | B75: =CONCATENATE(C75, "-", J75, "-", M75, "-", A75) -> 2023-PH074619000-1986-0428 | C75: =IF(OR(D75="Published", D75="Unpublished"), 2023, IF(D75="New", 2025, "")) -> 2023 | D75: Published | E75: Modified | F75: Yes | G75: NIR | H75: Negros Oriental | I75: Siaton | J75: PH074619000 | K75: Artificial Reef Development Program | L75: Site in San Jose | M75: 1986 | N75: 1985 | O75: 1987 | P75: Substrate Enhancement | Q75: Artificial Reef | R75: Tires | S75: Tires | T75: Not applicable | U75: Not applicable | V75: Tires | W75: "Reestablish a self-sustaining, functioning reef ecosystem", Reduce population declines and ecosystem degradation, "Provide alternative, sustainable livelihood opportunities" | X75: M2, M4, M5 | Y75: Support the government's food productivity, environmental protection and enhancement efforts; Support sustenance fishery; enhance and restore habitats; costal fishery management | Z75: BFAR | AA75: Development | AB75: Local | AC75: Government - NGA | AD75: BFAR | AE75: Unknown | AF75: Unknown | AG75: 45 units | AH75: BFAR | AI75: Government - NGA | AJ75: BFAR | AK75: Ministry of Human Settlements; Government organizations | AL75: NGOs | AM75: People's organizations; Fisher's associations | AN75: Peer-reviewed | AO75: Conference Proceeding | AP75: Balgos, M. C. (1995). Evaluation of artificial reef development in the Philippines. In J. L. Munro & M. C. Balgos (Eds.), Artificial reefs in the Philippines (ICLARM Conference Proceedings No. 49, pp. 6–22). International Center for Living Aquatic Resources Management (ICLARM). | AQ75: https://core.ac.uk/download/pdf/6515223.pdf | AR75: Miriam Balgos | AS75: Unknown
A76: 0431 | B76: =CONCATENATE(C76, "-", J76, "-", M76, "-", A76) -> 2023-PH074625000-1986-0431 | C76: =IF(OR(D76="Published", D76="Unpublished"), 2023, IF(D76="New", 2025, "")) -> 2023 | D76: Published | E76: Modified | F76: Yes | G76: NIR | H76: Negros Oriental | I76: Zamboanguita | J76: PH074625000 | K76: Artificial Reef Development Program | L76: Site in Poblacion | M76: 1986 | N76: 1985 | O76: 1987 | P76: Substrate Enhancement | Q76: Artificial Reef | R76: Tires | S76: Tires | T76: Not applicable | U76: Not applicable | V76: Tires | W76: "Reestablish a self-sustaining, functioning reef ecosystem", Reduce population declines and ecosystem degradation, "Provide alternative, sustainable livelihood opportunities" | X76: M2, M4, M5 | Y76: Support the government's food productivity, environmental protection and enhancement efforts; Support sustenance fishery; enhance and restore habitats; costal fishery management | Z76: BFAR | AA76: Development | AB76: Local | AC76: Government - NGA | AD76: BFAR | AE76: Unknown | AF76: Unknown | AG76: 42 units | AH76: BFAR | AI76: Government - NGA | AJ76: BFAR | AK76: Ministry of Human Settlements; Government organizations | AL76: NGOs | AM76: People's organizations; Fisher's associations | AN76: Peer-reviewed | AO76: Conference Proceeding | AP76: Balgos, M. C. (1995). Evaluation of artificial reef development in the Philippines. In J. L. Munro & M. C. Balgos (Eds.), Artificial reefs in the Philippines (ICLARM Conference Proceedings No. 49, pp. 6–22). International Center for Living Aquatic Resources Management (ICLARM). | AQ76: https://core.ac.uk/download/pdf/6515223.pdf | AR76: Miriam Balgos | AS76: Unknown
A77: 0448 | B77: =CONCATENATE(C77, "-", J77, "-", M77, "-", A77) -> 2023-PH153809000-1986-0448 | C77: =IF(OR(D77="Published", D77="Unpublished"), 2023, IF(D77="New", 2025, "")) -> 2023 | D77: Published | E77: Modified | F77: Yes | G77: BARMM | H77: Maguindanao del Norte | I77: Matanog | J77: PH153809000 | K77: Artificial Reef Development Program | L77: Site in Sugod Bay | M77: 1986 | N77: 1985 | O77: 1987 | P77: Substrate Enhancement | Q77: Artificial Reef | R77: Tires | S77: Tires | T77: Not applicable | U77: Not applicable | V77: Tires | W77: "Reestablish a self-sustaining, functioning reef ecosystem", Reduce population declines and ecosystem degradation, "Provide alternative, sustainable livelihood opportunities" | X77: M2, M4, M5 | Y77: Support the government's food productivity, environmental protection and enhancement efforts; Support sustenance fishery; enhance and restore habitats; costal fishery management | Z77: BFAR | AA77: Development | AB77: Local | AC77: Government - NGA | AD77: BFAR | AE77: Unknown | AF77: Unknown | AG77: Unknown | AH77: BFAR | AI77: Government - NGA | AJ77: BFAR | AK77: Ministry of Human Settlements; Government organizations | AL77: NGOs | AM77: People's organizations; Fisher's associations | AN77: Peer-reviewed | AO77: Conference Proceeding | AP77: Balgos, M. C. (1995). Evaluation of artificial reef development in the Philippines. In J. L. Munro & M. C. Balgos (Eds.), Artificial reefs in the Philippines (ICLARM Conference Proceedings No. 49, pp. 6–22). International Center for Living Aquatic Resources Management (ICLARM). | AQ77: https://core.ac.uk/download/pdf/6515223.pdf; https://www.ircwash.org/sites/default/files/802-PH90-8920.pdf | AR77: Miriam Balgos | AS77: Unknown
